<?xml version="1.0" encoding="utf-8"?>
<!-- This URDF was automatically created by SolidWorks to URDF Exporter! Originally created by Stephen Brawner (brawner@gmail.com) 
     Commit Version: 1.6.0-4-g7f85cfe  Build Version: 1.6.7995.38578
     For more information, please see http://wiki.ros.org/sw_urdf_exporter -->
<robot name="wxais_follower">
  <link name="base_link">
    <inertial>
      <origin xyz="0.00052268 -0.00005365 0.03202305" rpy="0 0 0"/>
      <mass value="0.45362020"/>
      <inertia ixx="0.00041296" ixy="-1.8e-7" ixz="-1.8e-6" iyy="0.00043677" iyz="3.8e-7" izz="0.00020350"/>
    </inertial>
    <visual>
      <origin xyz="0 0 0" rpy="0 0 0" />
      <geometry>
        <mesh filename="package://trossen_arm_description/meshes/wxais_follower/base_link.stl" />
      </geometry>
      <material name="">
        <color rgba="0.752941176470588 0.752941176470588 0.752941176470588 1" />
      </material>
    </visual>
    <collision>
      <origin xyz="0 0 0" rpy="0 0 0" />
      <geometry>
        <mesh filename="package://trossen_arm_description/meshes/wxais_follower/base_link.stl" />
      </geometry>
    </collision>
  </link>
  <link name="link_1">
    <inertial>
      <origin xyz="0.00021239 0.00381558 0.02072601" rpy="0 0 0"/>
      <mass value="0.15843428"/>
      <inertia ixx="0.00019568" ixy="5.8e-6" ixz="1.531e-5" iyy="0.00008633" iyz="5.45e-6" izz="0.00020268"/>
    </inertial>
    <visual>
      <origin xyz="0 0 0" rpy="0 0 0" />
      <geometry>
        <mesh filename="package://trossen_arm_description/meshes/wxais_follower/link_1.stl" />
      </geometry>
      <material name="">
        <color rgba="0.752941176470588 0.752941176470588 0.752941176470588 1" />
      </material>
    </visual>
    <collision>
      <origin xyz="0 0 0" rpy="0 0 0" />
      <geometry>
        <mesh filename="package://trossen_arm_description/meshes/wxais_follower/link_1.stl" />
      </geometry>
    </collision>
  </link>
  <joint name="joint_0" type="revolute">
    <origin xyz="0 0 0.05725" rpy="0 0 0" />
    <parent link="base_link" />
    <child link="link_1" />
    <axis xyz="0 0 1" />
    <limit lower="-3.14" upper="3.14" effort="27.0" velocity="3.14" />
  </joint>
  <link name="link_2">
    <inertial>
      <origin xyz="-0.13013162 -0.00289256 0.00043205" rpy="0 0 0"/>
      <mass value="1.18618542"/>
      <inertia ixx="0.00105929" ixy="4.62e-6" ixz="6.11e-5" iyy="0.01757805" iyz="1.87e-6" izz="0.01814288"/>
    </inertial>
    <visual>
      <origin xyz="0 0 0" rpy="0 0 0" />
      <geometry>
        <mesh filename="package://trossen_arm_description/meshes/wxais_follower/link_2.stl" />
      </geometry>
      <material name="">
        <color rgba="0.752941176470588 0.752941176470588 0.752941176470588 1" />
      </material>
    </visual>
    <collision>
      <origin xyz="0 0 0" rpy="0 0 0" />
      <geometry>
        <mesh filename="package://trossen_arm_description/meshes/wxais_follower/link_2.stl" />
      </geometry>
    </collision>
  </link>
  <joint name="joint_1" type="revolute">
    <origin xyz="0.02 0 0.04625" rpy="0 0 0" />
    <parent link="link_1" />
    <child link="link_2" />
    <axis xyz="0 1 0" />
    <limit lower="0.0" upper="2.356" effort="27.0" velocity="3.14" />
  </joint>
  <link name="link_3">
    <inertial>
      <origin xyz="0.20081085 -0.00148559 0.05715902" rpy="0 0 0"/>
      <mass value="1.08254926"/>
      <inertia ixx="0.00096248" ixy="-1.11e-4" ixz="5.91e-4" iyy="0.00690323" iyz="-1.21e-5" izz="0.00717548"/>
    </inertial>
    <visual>
      <origin xyz="0 0 0" rpy="0 0 0" />
      <geometry>
        <mesh filename="package://trossen_arm_description/meshes/wxais_follower/link_3.stl" />
      </geometry>
      <material name="">
        <color rgba="0.752941176470588 0.752941176470588 0.752941176470588 1" />
      </material>
    </visual>
    <collision>
      <origin xyz="0 0 0" rpy="0 0 0" />
      <geometry>
        <mesh filename="package://trossen_arm_description/meshes/wxais_follower/link_3.stl" />
      </geometry>
    </collision>
  </link>
  <joint name="joint_2" type="revolute">
    <origin xyz="-0.264 0 0" rpy="0 0 0" />
    <parent link="link_2" />
    <child link="link_3" />
    <axis xyz="0 -1 0" />
    <limit lower="-3.14" upper="3.14" effort="0" velocity="0" />
  </joint>
  <link name="link_4">
    <inertial>
      <origin xyz="0.05715387 0.00034278 0.05714934" rpy="0 0 0"/>
      <mass value="0.43735051"/>
      <inertia ixx="0.00051288" ixy="-7.84e-6" ixz="1.73e-4" iyy="0.00062611" iyz="-7.96e-6" izz="0.00040480"/>
    </inertial>
    <visual>
      <origin xyz="0 0 0" rpy="0 0 0" />
      <geometry>
        <mesh filename="package://trossen_arm_description/meshes/wxais_follower/link_4.stl" />
      </geometry>
      <material name="">
        <color rgba="0.752941176470588 0.752941176470588 0.752941176470588 1" />
      </material>
    </visual>
    <collision>
      <origin xyz="0 0 0" rpy="0 0 0" />
      <geometry>
        <mesh filename="package://trossen_arm_description/meshes/wxais_follower/link_4.stl" />
      </geometry>
    </collision>
  </link>
  <joint name="joint_3" type="revolute">
    <origin xyz="0.245 0 0.06" rpy="0 0 0" />
    <parent link="link_3" />
    <child link="link_4" />
    <axis xyz="0 -1 0" />
    <limit lower="-1.571" upper="1.571" effort="7.0" velocity="3.14" />
  </joint>
  <link name="link_5">
    <inertial>
      <origin xyz="0.00386239 -0.00001131 -0.04318054" rpy="0 0 0"/>
      <mass value="0.36982410"/>
      <inertia ixx="0.00018840" ixy="4.5e-7" ixz="2.45e-6" iyy="0.00032339" iyz="-3e-8" izz="0.00026992"/>
    </inertial>
    <visual>
      <origin xyz="0 0 0" rpy="0 0 0" />
      <geometry>
        <mesh filename="package://trossen_arm_description/meshes/wxais_follower/link_5.stl" />
      </geometry>
      <material name="">
        <color rgba="0.752941176470588 0.752941176470588 0.752941176470588 1" />
      </material>
    </visual>
    <collision>
      <origin xyz="0 0 0" rpy="0 0 0" />
      <geometry>
        <mesh filename="package://trossen_arm_description/meshes/wxais_follower/link_5.stl" />
      </geometry>
    </collision>
  </link>
  <joint name="joint_4" type="revolute">
    <origin xyz="0.06775 0 0.0455" rpy="0 0 0" />
    <parent link="link_4" />
    <child link="link_5" />
    <axis xyz="0 0 -1" />
    <limit lower="-1.571" upper="1.571" effort="7.0" velocity="3.14" />
  </joint>
  <link name="link_6">
    <inertial>
      <origin xyz="0.04551 0.00051 0.00947" rpy="0 0 0"/>
      <mass value="0.63463"/>
      <inertia ixx="0.86891" ixy="-0.00023699" ixz="0.04879" iyy="0.75399" iyz="0.01658" izz="0.88386"/>
    </inertial>
    <visual>
      <origin xyz="0 0 0" rpy="0 0 0" />
      <geometry>
        <mesh filename="package://trossen_arm_description/meshes/wxais_follower/link_6.stl" />
      </geometry>
      <material name="">
        <color rgba="0.752941176470588 0.752941176470588 0.752941176470588 1" />
      </material>
    </visual>
    <collision>
      <origin xyz="0 0 0" rpy="0 0 0" />
      <geometry>
        <mesh filename="package://trossen_arm_description/meshes/wxais_follower/link_6.stl" />
      </geometry>
    </collision>
  </link>
  <joint name="joint_5" type="revolute">
    <origin xyz="0.02895 0 -0.0455" rpy="0 0 0" />
    <parent link="link_5" />
    <child link="link_6" />
    <axis xyz="1 0 0" />
    <limit lower="-3.14" upper="3.14" effort="7.0" velocity="3.14" />
  </joint>
  <link name="gripper_left">
    <inertial>
      <origin xyz="0.00780825 -0.00528697 -0.00368479" rpy="0 0 0"/>
      <mass value="0.07618477"/>
      <inertia ixx="0.00002759" ixy="-0.00000495" ixz="-0.00000052" iyy="0.00003194" iyz="0.00000327" izz="0.00003791"/>
    </inertial>
    <visual>
      <origin xyz="0 0 0" rpy="0 0 0" />
      <geometry>
        <mesh filename="package://trossen_arm_description/meshes/wxais_follower/gripper_left.stl" />
      </geometry>
      <material name="">
        <color rgba="0.752941176470588 0.752941176470588 0.752941176470588 1" />
      </material>
    </visual>
    <collision>
      <origin xyz="0 0 0" rpy="0 0 0" />
      <geometry>
        <mesh filename="package://trossen_arm_description/meshes/wxais_follower/gripper_left.stl" />
      </geometry>
    </collision>
  </link>
  <joint name="joint_gl" type="prismatic">
    <origin xyz="0.078 0.021375 0" rpy="0 0 0" />
    <parent link="link_6" />
    <child link="gripper_left" />
    <axis xyz="0 1 0" />
    <limit lower="0" upper="0.044" effort="400.0" velocity="0.0875" />
  </joint>
  <link name="gripper_right">
    <inertial>
      <origin xyz="0.00780824 0.00528691 0.00221090" rpy="0 0 0"/>
      <mass value="0.07618477"/>
      <inertia ixx="0.00002759" ixy="0.00000495" ixz="-0.00000275" iyy="0.00003194" iyz="0.00000203" izz="0.00003791"/>
    </inertial>
    <visual>
      <origin xyz="0 0 0" rpy="0 0 0" />
      <geometry>
        <mesh filename="package://trossen_arm_description/meshes/wxais_follower/gripper_right.stl" />
      </geometry>
      <material name="">
        <color rgba="0.752941176470588 0.752941176470588 0.752941176470588 1" />
      </material>
    </visual>
    <collision>
      <origin xyz="0 0 0" rpy="0 0 0" />
      <geometry>
        <mesh filename="package://trossen_arm_description/meshes/wxais_follower/gripper_right.stl" />
      </geometry>
    </collision>
  </link>
  <joint name="joint_gr" type="prismatic">
    <origin xyz="0.078 -0.021375 0" rpy="0 0 0" />
    <parent link="link_6" />
    <child link="gripper_right" />
    <axis xyz="0 -1 0" />
    <limit lower="-0.044" upper="0.0" effort="400.0" velocity="0.0875" />
  </joint>
</robot>
