<?xml version="1.0" encoding="utf-8"?>
<robot name="wxai" xmlns:xacro="http://ros.org/wiki/xacro">

  <xacro:property name="robot_model"
    value="wxai"
    scope="global"/>
  <xacro:property name="dof"
    value="6"
    scope="global"/>

  <xacro:arg name="variant"                         default="leader"/>      <!-- 'base', 'leader', 'follower' -->
  <xacro:arg name="arm_side"                        default="right"/>          <!-- '', 'left', 'right' -->
  <xacro:arg name="use_world_frame"                 default="false"/>     <!-- 'true', 'false' -->
  <xacro:arg name="base_link_frame"                 default="base_link"/>

  <xacro:property name="mesh_directory"             value="package://trossen_arm_description/meshes/${robot_model}"/>
  <xacro:property name="variant"                    value="$(arg variant)"/>
  <xacro:property name="arm_side"                   value="$(arg arm_side)"/>

  <xacro:if value="$(arg use_world_frame)">
    <link name="world"/>
    <joint name="fixed" type="fixed">
      <parent
        link="world"/>
      <child
        link="$(arg base_link_frame)"/>
    </joint>
  </xacro:if> <!-- use_world_frame -->

  <link name="base_link">
    <inertial>
      <origin
        xyz="-0.000375858292607297 -6.62873423389478E-05 0.027443162348488"
        rpy="0 0 0" />
      <mass value="0.45969858" />
      <inertia
        ixx="0.00088006"
        ixy="-0.00000011"
        ixz="0.00000247"
        iyy="0.00091243"
        iyz="0.00000001"
        izz="0.00021404" />
    </inertial>
    <visual>
      <origin
        xyz="0 0 0"
        rpy="0 0 0" />
      <geometry>
        <mesh filename="${mesh_directory}/base_link.stl" />
      </geometry>
      <material name="">
        <color rgba="0.752941176470588 0.752941176470588 0.752941176470588 1" />
      </material>
    </visual>
    <collision>
      <origin
        xyz="0 0 0"
        rpy="0 0 0" />
      <geometry>
        <mesh filename="${mesh_directory}/base_link.stl" />
      </geometry>
    </collision>
  </link>

  <link name="link_1">
    <inertial>
      <origin
        xyz="-0.000170717140750964 0.00142938385871949 0.0203939511450044"
        rpy="0 0 0" />
      <mass value="0.15270428" />
      <inertia
        ixx="0.00024937"
        ixy="0.00000188"
        ixz="0.00001402"
        iyy="0.00014741"
        iyz="0.00000665"
        izz="0.00019264" />
    </inertial>
    <visual>
      <origin
        xyz="0 0 0"
        rpy="0 0 0" />
      <geometry>
        <mesh filename="${mesh_directory}/link_1.stl" />
      </geometry>
      <material name="">
        <color rgba="0.752941176470588 0.752941176470588 0.752941176470588 1" />
      </material>
    </visual>
    <collision>
      <origin
        xyz="0 0 0"
        rpy="0 0 0" />
      <geometry>
        <mesh filename="${mesh_directory}/link_1.stl" />
      </geometry>
    </collision>
  </link>

  <joint name="joint_0" type="revolute">
    <origin
      xyz="0 0 0.05725"
      rpy="0 0 0" />
    <parent link="base_link" />
    <child link="link_1" />
    <axis xyz="0 0 1" />
    <limit
      lower="-${pi}"
      upper="${pi}"
      effort="0"
      velocity="0" />
  </joint>

  <link name="link_2">
    <inertial>
      <origin
        xyz="-0.130142256375337 -0.00167447142265246 0.000487627804054119"
        rpy="0 0 0" />
      <mass value="1.15316319" />
      <inertia
        ixx="0.00103625"
        ixy="0.00044590"
        ixz="-0.00000551"
        iyy="0.03721553"
        iyz="0.00000121"
        izz="0.03780905" />
    </inertial>
    <visual>
      <origin
        xyz="0 0 0"
        rpy="0 0 0" />
      <geometry>
        <mesh filename="${mesh_directory}/link_2.stl" />
      </geometry>
      <material name="">
        <color rgba="0.752941176470588 0.752941176470588 0.752941176470588 1" />
      </material>
    </visual>
    <collision>
      <origin
        xyz="0 0 0"
        rpy="0 0 0" />
      <geometry>
        <mesh filename="${mesh_directory}/link_2.stl" />
      </geometry>
    </collision>
  </link>

  <joint name="joint_1" type="revolute">
    <origin
      xyz="0.02 0 0.04625"
      rpy="0 0 0" />
    <parent link="link_1" />
    <child link="link_2" />
    <axis xyz="0 1 0" />
    <limit
      lower="-${pi}"
      upper="${pi}"
      effort="0"
      velocity="0" />
  </joint>

  <link name="link_3">
    <inertial>
      <origin
        xyz="0.14889637986769 -0.000482795993009637 0.0533160727860036"
        rpy="0 0 0" />
      <mass value="0.68666638" />
      <inertia
        ixx="0.00276824"
        ixy="-0.00020811"
        ixz="0.00741781"
        iyy="0.03004807"
        iyz="-0.00004748"
        izz="0.02807083" />
    </inertial>
    <visual>
      <origin
        xyz="0 0 0"
        rpy="0 0 0" />
      <geometry>
        <mesh filename="${mesh_directory}/link_3.stl" />
      </geometry>
      <material name="">
        <color rgba="0.752941176470588 0.752941176470588 0.752941176470588 1" />
      </material>
    </visual>
    <collision>
      <origin
        xyz="0 0 0"
        rpy="0 0 0" />
      <geometry>
        <mesh filename="${mesh_directory}/link_3.stl" />
      </geometry>
    </collision>
  </link>

  <joint name="joint_2" type="revolute">
    <origin
      xyz="-0.264 0 0"
      rpy="0 0 0" />
    <parent link="link_2" />
    <child link="link_3" />
    <axis xyz="0 -1 0" />
    <limit
      lower="-${pi}"
      upper="${pi}"
      effort="0"
      velocity="0" />
  </joint>

  <link name="link_4">
    <inertial>
      <origin
        xyz="0.0499341120147654 0.000395925820699807 0.0525216081324763"
        rpy="0 0 0" />
      <mass value="0.45789905" />
      <inertia
        ixx="0.00212398"
        ixy="0.00000031"
        ixz="0.00174386"
        iyy="0.00378616"
        iyz="0.00000007"
        izz="0.00196042" />
    </inertial>
    <visual>
      <origin
        xyz="0 0 0"
        rpy="0 0 0" />
      <geometry>
        <mesh filename="${mesh_directory}/link_4.stl" />
      </geometry>
      <material name="">
        <color rgba="0.752941176470588 0.752941176470588 0.752941176470588 1" />
      </material>
    </visual>
    <collision>
      <origin
        xyz="0 0 0"
        rpy="0 0 0" />
      <geometry>
        <mesh filename="${mesh_directory}/link_4.stl" />
      </geometry>
    </collision>
  </link>

  <joint name="joint_3" type="revolute">
    <origin
      xyz="0.245 0 0.06"
      rpy="0 0 0" />
    <parent link="link_3" />
    <child link="link_4" />
    <axis xyz="0 -1 0" />
    <limit
      lower="-${pi}"
      upper="${pi}"
      effort="0"
      velocity="0" />
  </joint>

  <link name="link_5">
    <inertial>
      <origin
        xyz="0.00412447 -0.00001138 -0.04283184"
        rpy="0 0 0" />
      <mass value="0.36693910" />
      <inertia
        ixx="0.00086230"
        ixy="0.00000044"
        ixz="-0.00006573"
        iyy="0.00100004"
        iyz="0.00000015"
        izz="0.00027375" />
    </inertial>
    <visual>
      <origin
        xyz="0 0 0"
        rpy="0 0 0" />
      <geometry>
        <mesh filename="${mesh_directory}/link_5.stl" />
      </geometry>
      <material name="">
        <color rgba="0.752941176470588 0.752941176470588 0.752941176470588 1" />
      </material>
    </visual>
    <collision>
      <origin
        xyz="0 0 0"
        rpy="0 0 0" />
      <geometry>
        <mesh filename="${mesh_directory}/link_5.stl" />
      </geometry>
    </collision>
  </link>

  <joint name="joint_4" type="revolute">
    <origin
      xyz="0.06775 0 0.0455"
      rpy="0 0 0" />
    <parent link="link_4" />
    <child link="link_5" />
    <axis xyz="0 0 -1" />
    <limit
      lower="-${pi}"
      upper="${pi}"
      effort="0"
      velocity="0" />
  </joint>

  <link name="link_6">
    <inertial>
      <origin
        xyz="0.0454447042226515 -3.3312119305551E-05 6.37079439202992E-09"
        rpy="0 0 0" />
      <mass value="0.55469347" />
      <inertia
        ixx="0.00082429"
        ixy="0.00000033"
        ixz="0.00000026"
        iyy="0.00164746"
        iyz="-0.00000004"
        izz="0.00224588" />
    </inertial>
    <visual>
      <origin
        xyz="0 0 0"
        rpy="0 0 0" />
      <geometry>
        <mesh filename="${mesh_directory}/link_6.stl" />
      </geometry>
      <material name="">
        <color rgba="0.752941176470588 0.752941176470588 0.752941176470588 1" />
      </material>
    </visual>
    <collision>
      <origin
        xyz="0 0 0"
        rpy="0 0 0" />
      <geometry>
        <mesh filename="${mesh_directory}/link_6.stl" />
      </geometry>
    </collision>
  </link>

  <joint name="joint_5" type="revolute">
    <origin
      xyz="0.02895 0 -0.0455"
      rpy="0 0 0" />
    <parent link="link_5" />
    <child link="link_6" />
    <axis xyz="1 0 0" />
    <limit
      lower="-${pi}"
      upper="${pi}"
      effort="0"
      velocity="0" />
  </joint>

  <link name="carriage_right">
    <inertial>
      <origin
        xyz="-0.0088960216342942 0.00403514361427389 0.00457900737971173"
        rpy="0 0 0" />
      <mass value="0.05036313" />
      <inertia
        ixx="0.00001923"
        ixy="-0.00000345"
        ixz="-0.00000309"
        iyy="0.00001096"
        iyz="0.00000265"
        izz="0.00001858" />
    </inertial>
    <visual>
      <origin
        xyz="0 0 0"
        rpy="0 0 0" />
      <geometry>
        <mesh filename="${mesh_directory}/carriage_right.stl" />
      </geometry>
      <material name="">
        <color rgba="0.752941176470588 0.752941176470588 0.752941176470588 1" />
      </material>
    </visual>
    <collision>
      <origin
        xyz="0 0 0"
        rpy="0 0 0" />
      <geometry>
        <mesh filename="${mesh_directory}/carriage_right.stl" />
      </geometry>
    </collision>
  </link>

  <joint name="right_carriage_joint" type="prismatic">
    <origin
      xyz="0.0745 -0.023 0"
      rpy="0 0 0" />
    <parent link="link_6" />
    <child link="carriage_right" />
    <axis xyz="0 -1 0" />
    <limit
      lower="0"
      upper="0"
      effort="0"
      velocity="0" />
  </joint>

  <link name="carriage_left">
    <inertial>
      <origin
        xyz="-0.00889602163429412 -0.00403515225638459 -0.00457907970794055"
        rpy="0 0 0" />
      <mass value="0.05036313" />
      <inertia
        ixx="0.00001923"
        ixy="0.00000345"
        ixz="0.00000309"
        iyy="0.00001096"
        iyz="0.00000265"
        izz="0.00001858" />
    </inertial>
    <visual>
      <origin
        xyz="0 0 0"
        rpy="0 0 0" />
      <geometry>
        <mesh filename="${mesh_directory}/carriage_left.stl" />
      </geometry>
      <material name="">
        <color rgba="0.752941176470588 0.752941176470588 0.752941176470588 1" />
      </material>
    </visual>
    <collision>
      <origin
        xyz="0 0 0"
        rpy="0 0 0" />
      <geometry>
        <mesh filename="${mesh_directory}/carriage_left.stl" />
      </geometry>
    </collision>
  </link>

  <joint name="left_carriage_joint" type="prismatic">
    <origin
      xyz="0.0745 0.023 0"
      rpy="0 0 0" />
    <parent link="link_6" />
    <child link="carriage_left" />
    <axis xyz="0 1 0" />
    <limit
      lower="0"
      upper="0"
      effort="0"
      velocity="0" />
  </joint>

  <xacro:if value="${variant == 'follower'}">

    <link name="camera_mount">
      <inertial>
        <origin
          xyz="0.0296855854757168 0.00562972530248117 0.0471179075194367"
          rpy="0 0 0" />
        <mass value="0.04518012" />
        <inertia
          ixx="0.00014960"
          ixy="0.00000956"
          ixz="0.00007148"
          iyy="0.00017435"
          iyz="0.00001857"
          izz="0.00006808" />
      </inertial>
      <visual>
        <origin
          xyz="0 0 0"
          rpy="0 0 0" />
        <geometry>
          <mesh filename="${mesh_directory}/camera_mount.stl" />
        </geometry>
        <material name="">
          <color rgba="0.752941176470588 0.752941176470588 0.752941176470588 1" />
        </material>
      </visual>
      <collision>
        <origin
          xyz="0 0 0"
          rpy="0 0 0" />
        <geometry>
          <mesh filename="${mesh_directory}/camera_mount.stl" />
        </geometry>
      </collision>
    </link>

    <joint name="camera_mount_joint" type="fixed">
      <origin
        xyz="0 0 0"
        rpy="0 0 0" />
      <parent link="link_6" />
      <child link="camera_mount" />
      <axis xyz="0 0 0" />
    </joint>

  </xacro:if> <!-- variant == 'follower' -->

  <xacro:if value="${variant == 'leader'}">

    <xacro:if value="${arm_side == 'left'}">

      <link name="handle">
        <inertial>
          <origin
            xyz="0.0203255017535234 -0.00738697181677922 -0.081111420473222"
            rpy="0 0 0" />
          <mass value="0.05670184" />
          <inertia
            ixx="0.00042154"
            ixy="-0.00000774"
            ixz="-0.00008119"
            iyy="0.00044231"
            iyz="0.00003707"
            izz="0.00003893"
            />
        </inertial>
        <visual>
          <origin
            xyz="0 0 0"
            rpy="0 0 0" />
          <geometry>
            <mesh filename="${mesh_directory}/handle_left.stl" />
          </geometry>
          <material name="">
            <color rgba="0.752941176470588 0.752941176470588 0.752941176470588 1" />
          </material>
        </visual>
        <collision>
          <origin
            xyz="0 0 0"
            rpy="0 0 0" />
          <geometry>
            <mesh filename="${mesh_directory}/handle_left.stl" />
          </geometry>
        </collision>
      </link>

      <joint name="handle_joint" type="fixed">
        <origin
          xyz="0 0 0"
          rpy="0 0 0" />
        <parent link="link_6" />
        <child link="handle" />
        <axis xyz="0 0 0" />
      </joint>

      <link name="leader_finger_left_index">
        <inertial>
          <origin
            xyz="0.00470472514618581 0.0029289423469383 -0.0226793519809421"
            rpy="0 0 0" />
          <mass value="0.02647075" />
          <inertia
            ixx="0.00003230"
            ixy="0.00000009"
            ixz="-0.00000168"
            iyy="0.00003143"
            iyz="-0.00000390"
            izz="0.00000380" />
        </inertial>
        <visual>
          <origin
            xyz="0 0 0"
            rpy="0 0 0" />
          <geometry>
            <mesh filename="${mesh_directory}/leader_finger_left_index.stl" />
          </geometry>
          <material name="">
            <color rgba="0.752941176470588 0.752941176470588 0.752941176470588 1" />
          </material>
        </visual>
        <collision>
          <origin
            xyz="0 0 0"
            rpy="0 0 0" />
          <geometry>
            <mesh filename="${mesh_directory}/leader_finger_left_index.stl" />
          </geometry>
        </collision>
      </link>

      <joint name="left_index_joint" type="fixed">
        <origin
          xyz="0 0 0"
          rpy="0 0 0" />
        <parent link="carriage_left" />
        <child link="leader_finger_left_index" />
        <axis xyz="0 0 0" />
      </joint>

      <link name="leader_finger_left_thumb">
        <inertial>
          <origin
            xyz="-0.00139067941257306 -0.00434572084089531 -0.0280809769238789"
            rpy="0 0 0" />
          <mass value="0.02088075" />
          <inertia
            ixx="0.00003399"
            ixy="0.00000062"
            ixz="0.00000315"
            iyy="0.00003270"
            iyz="0.00000479"
            izz="0.00000358" />
        </inertial>
        <visual>
          <origin
            xyz="0 0 0"
            rpy="0 0 0" />
          <geometry>
            <mesh filename="${mesh_directory}/leader_finger_left_thumb.stl" />
          </geometry>
          <material name="">
            <color rgba="0.752941176470588 0.752941176470588 0.752941176470588 1" />
          </material>
        </visual>
        <collision>
          <origin
            xyz="0 0 0"
            rpy="0 0 0" />
          <geometry>
            <mesh filename="${mesh_directory}/leader_finger_left_thumb.stl" />
          </geometry>
        </collision>
      </link>

      <joint name="left_thumb_joint" type="fixed">
        <origin
          xyz="0 0 0"
          rpy="0 0 0" />
        <parent link="carriage_right" />
        <child link="leader_finger_left_thumb" />
        <axis xyz="0 0 0" />
      </joint>

    </xacro:if> <!-- arm_side == 'left' -->

    <xacro:if value="${arm_side == 'right'}">

      <link name="handle">
        <inertial>
          <origin
            xyz="0.0203252458247983 0.0073869167553635 -0.0811185578133218"
            rpy="0 0 0" />
          <mass value="0.05668184" />
          <inertia
            ixx="0.00042144"
            ixy="0.00000773"
            ixz="-0.00008117"
            iyy="0.00044221"
            iyz="-0.00003705"
            izz="0.00003891" />
        </inertial>
        <visual>
          <origin
            xyz="0 0 0"
            rpy="0 0 0" />
          <geometry>
            <mesh filename="${mesh_directory}/handle_right.stl" />
          </geometry>
          <material name="">
            <color rgba="0.752941176470588 0.752941176470588 0.752941176470588 1" />
          </material>
        </visual>
        <collision>
          <origin
            xyz="0 0 0"
            rpy="0 0 0" />
          <geometry>
            <mesh filename="${mesh_directory}/handle_right.stl" />
          </geometry>
        </collision>
      </link>

      <joint name="handle_joint" type="fixed">
        <origin
          xyz="0 0 0"
          rpy="0 0 0" />
        <parent link="link_6" />
        <child link="handle" />
        <axis xyz="0 0 0" />
      </joint>

      <link name="leader_finger_right_thumb">
        <inertial>
          <origin
            xyz="-0.00139125804767926 0.00434423906746726 -0.0280833807733366"
            rpy="0 0 0" />
          <mass value="0.02089075" />
          <inertia
            ixx="0.00003402"
            ixy="-0.00000062"
            ixz="0.00000315"
            iyy="0.00003273"
            iyz="-0.00000480"
            izz="0.00000358" />
        </inertial>
        <visual>
          <origin
            xyz="0 0 0"
            rpy="0 0 0" />
          <geometry>
            <mesh filename="${mesh_directory}/leader_finger_right_thumb.stl" />
          </geometry>
          <material name="">
            <color rgba="0.752941176470588 0.752941176470588 0.752941176470588 1" />
          </material>
        </visual>
        <collision>
          <origin
            xyz="0 0 0"
            rpy="0 0 0" />
          <geometry>
            <mesh filename="${mesh_directory}/leader_finger_right_thumb.stl" />
          </geometry>
        </collision>
      </link>

      <joint name="right_thumb_joint" type="fixed">
        <origin
          xyz="0 0 0"
          rpy="0 0 0" />
        <parent link="carriage_left" />
        <child link="leader_finger_right_thumb" />
        <axis xyz="0 0 0" />
      </joint>

      <link name="leader_finger_right_index">
        <inertial>
          <origin
            xyz="0.00470571265625336 -0.0029303338205246 -0.0226797825244652"
            rpy="0 0 0" />
          <mass value="0.02649075" />
          <inertia
            ixx="0.00003233"
            ixy="-0.00000009"
            ixz="-0.00000168"
            iyy="0.00003146"
            iyz="0.00000391"
            izz="0.00000381" />
        </inertial>
        <visual>
          <origin
            xyz="0 0 0"
            rpy="0 0 0" />
          <geometry>
            <mesh filename="${mesh_directory}/leader_finger_right_index.stl" />
          </geometry>
          <material name="">
            <color rgba="0.752941176470588 0.752941176470588 0.752941176470588 1" />
          </material>
        </visual>
        <collision>
          <origin
            xyz="0 0 0"
            rpy="0 0 0" />
          <geometry>
            <mesh filename="${mesh_directory}/leader_finger_right_index.stl" />
          </geometry>
        </collision>
      </link>

      <joint name="right_index_joint" type="fixed">
        <origin
          xyz="0 0 0"
          rpy="0 0 0" />
        <parent link="carriage_right" />
        <child link="leader_finger_right_index" />
        <axis xyz="0 0 0" />
      </joint>

    </xacro:if> <!-- leader_polarity == 'right' -->

  </xacro:if> <!-- variant == 'leader' -->

  <xacro:if value="${variant in ('base', 'follower')}">

    <link name="gripper_left">
      <inertial>
        <origin
          xyz="0.0188673477391189 -0.00900068987997303 -0.00215891070969232"
          rpy="0 0 0" />
        <mass value="0.03090787" />
        <inertia
          ixx=" 0.00001034"
          ixy="-0.00000849"
          ixz="-0.00000155"
          iyy="0.00002610"
          iyz="0.00000080"
          izz="0.00002544" />
      </inertial>
      <visual>
        <origin
          xyz="0 0 0"
          rpy="0 0 0" />
        <geometry>
          <mesh filename="${mesh_directory}/gripper_left.stl" />
        </geometry>
        <material name="">
          <color rgba="0.752941176470588 0.752941176470588 0.752941176470588 1" />
        </material>
      </visual>
      <collision>
        <origin
          xyz="0 0 0"
          rpy="0 0 0" />
        <geometry>
          <mesh filename="${mesh_directory}/gripper_left.stl" />
        </geometry>
      </collision>
    </link>

    <joint name="left_gripper_joint" type="fixed">
      <origin
        xyz="0 0 0"
        rpy="0 0 0" />
      <parent link="carriage_left" />
      <child link="gripper_left" />
      <axis xyz="0 0 0" />
    </joint>

    <link name="gripper_right">
      <inertial>
        <origin
          xyz="0.0188673150206433 0.00900062850131636 -0.00215899211667148"
          rpy="0 0 0" />
        <mass value="0.03090786" />
        <inertia
          ixx="0.00001034"
          ixy="0.00000849"
          ixz=" -0.00000155"
          iyy="0.00002610"
          iyz="-0.00000080"
          izz="0.00002544" />
      </inertial>
      <visual>
        <origin
          xyz="0 0 0"
          rpy="0 0 0" />
        <geometry>
          <mesh filename="${mesh_directory}/gripper_right.stl" />
        </geometry>
        <material name="">
          <color rgba="0.752941176470588 0.752941176470588 0.752941176470588 1" />
        </material>
      </visual>
      <collision>
        <origin
          xyz="0 0 0"
          rpy="0 0 0" />
        <geometry>
          <mesh filename="${mesh_directory}/gripper_right.stl" />
        </geometry>
      </collision>
    </link>

    <joint name="right_gripper_joint" type="fixed">
      <origin
        xyz="0 0 0"
        rpy="0 0 0" />
      <parent link="carriage_right" />
      <child link="gripper_right" />
      <axis xyz="0 0 0" />
    </joint>

  </xacro:if> <!-- variant in ('base', 'follower') -->

</robot>
