<?xml version="1.0" encoding="utf-8"?>
<!-- This URDF was automatically created by SolidWorks to URDF Exporter! Originally created by Stephen Brawner (brawner@gmail.com)
     Commit Version: 1.6.0-4-g7f85cfe  Build Version: 1.6.7995.38578
     For more information, please see http://wiki.ros.org/sw_urdf_exporter -->
<robot name="leader">
  <link
    name="base_link">
    <inertial>
      <origin
        xyz="0.00010756571967135 -2.02726537459036E-05 0.0343566351665907"
        rpy="-1.57079632679 0 0" />
      <mass
        value="0.506427227378768" />
      <inertia
        ixx="0.000410849158294362"
        ixy="-2.6390857577999E-12"
        ixz="6.4642046779666E-08"
        iyy="0.000410583719677176"
        iyz="8.11610951346684E-09"
        izz="0.000748456860289781" />
    </inertial>
    <visual>
      <origin
        xyz="0 0 0"
        rpy="-1.57079632679 0 0" />
      <geometry>
        <mesh
          filename="package://trossen_arm_description/meshes/leader/base_link.STL" />
      </geometry>
      <material
        name="">
        <color
          rgba="0.752941176470588 0.752941176470588 0.752941176470588 1" />
      </material>
    </visual>
    <collision>
      <origin
        xyz="0 0 0"
        rpy="-1.57079632679 0 0" />
      <geometry>
        <mesh
          filename="package://trossen_arm_description/meshes/leader/base_link.STL" />
      </geometry>
    </collision>
  </link>
  <link
    name="link_1">
    <inertial>
      <origin
        xyz="0.0183087687009895 -0.00169029827830938 0.0313917966334055"
        rpy="0 0 0" />
      <mass
        value="0.170036201199718" />
      <inertia
        ixx="6.64163178287466E-05"
        ixy="3.19906518866073E-13"
        ixz="-1.15422775710597E-07"
        iyy="6.97138403587758E-05"
        iyz="8.11589333400231E-09"
        izz="7.34348406475318E-05" />
    </inertial>
    <visual>
      <origin
        xyz="0 0 0"
        rpy="0 0 0" />
      <geometry>
        <mesh
          filename="package://trossen_arm_description/meshes/leader/link_1.STL" />
      </geometry>
      <material
        name="">
        <color
          rgba="0.752941176470588 0.752941176470588 0.752941176470588 1" />
      </material>
    </visual>
    <collision>
      <origin
        xyz="0 0 0"
        rpy="0 0 0" />
      <geometry>
        <mesh
          filename="package://trossen_arm_description/meshes/leader/link_1.STL" />
      </geometry>
    </collision>
  </link>
  <joint
    name="joint_0"
    type="revolute">
    <origin
      xyz="0 0 0.081223"
      rpy="0 0 0" />
    <parent
      link="base_link" />
    <child
      link="link_1" />
    <axis
      xyz="0 0 1" />
    <limit
      lower="-3.14159265359"
      upper="3.14159265359"
      effort="0"
      velocity="0" />
  </joint>
  <link
    name="link_2">
    <inertial>
      <origin
        xyz="0.00865539205163852 -0.000520109652861108 0.216602533083434"
        rpy="0 0 0" />
      <mass
        value="0.54100320866163" />
      <inertia
        ixx="0.00137090051100915"
        ixy="7.01777343227621E-09"
        ixz="-5.84588421589974E-06"
        iyy="0.00136565822034603"
        iyz="-4.03578240311136E-09"
        izz="0.000107501803426731" />
    </inertial>
    <visual>
      <origin
        xyz="0 0 0"
        rpy="0 0 0" />
      <geometry>
        <mesh
          filename="package://trossen_arm_description/meshes/leader/link_2.STL" />
      </geometry>
      <material
        name="">
        <color
          rgba="0.752941176470588 0.752941176470588 0.752941176470588 1" />
      </material>
    </visual>
    <collision>
      <origin
        xyz="0 0 0"
        rpy="0 0 0" />
      <geometry>
        <mesh
          filename="package://trossen_arm_description/meshes/leader/link_2.STL" />
      </geometry>
    </collision>
  </link>
  <joint
    name="joint_1"
    type="revolute">
    <origin
      xyz="0.02 0 0.035"
      rpy="0 0 0" />
    <parent
      link="link_1" />
    <child
      link="link_2" />
    <axis
      xyz="0 -1 0" />
    <limit
      lower="-2.4"
      upper="1.87"
      effort="0"
      velocity="0" />
  </joint>
  <link
    name="link_3">
    <inertial>
      <origin
        xyz="0.116840604141165 -0.000678737535719068 0.0537736076061675"
        rpy="0 0 0" />
      <mass
        value="0.303446681927526" />
      <inertia
        ixx="9.61115485045656E-05"
        ixy="-4.05930567102677E-09"
        ixz="-2.33283733883263E-05"
        iyy="0.000199643341936564"
        iyz="-7.00409767018677E-09"
        izz="0.000158700505319796" />
    </inertial>
    <visual>
      <origin
        xyz="0 0 0"
        rpy="0 0 0" />
      <geometry>
        <mesh
          filename="package://trossen_arm_description/meshes/leader/link_3.STL" />
      </geometry>
      <material
        name="">
        <color
          rgba="0.752941176470588 0.752941176470588 0.752941176470588 1" />
      </material>
    </visual>
    <collision>
      <origin
        xyz="0 0 0"
        rpy="0 0 0" />
      <geometry>
        <mesh
          filename="package://trossen_arm_description/meshes/leader/link_3.STL" />
      </geometry>
    </collision>
  </link>
  <joint
    name="joint_2"
    type="revolute">
    <origin
      xyz="0.03 0 0.35"
      rpy="0 0 0" />
    <parent
      link="link_2" />
    <child
      link="link_3" />
    <axis
      xyz="0 -1 0" />
    <limit
      lower="-1.86"
      upper="2.28"
      effort="0"
      velocity="0" />
  </joint>
  <link
    name="link_4">
    <inertial>
      <origin
        xyz="0.0636872025032118 4.15835862129295E-05 -0.000847055499594185"
        rpy="0 0 0" />
      <mass
        value="0.211552053843195" />
      <inertia
        ixx="0.000115244428123329"
        ixy="-2.20918148593346E-08"
        ixz="8.11555403596931E-09"
        iyy="8.75465189519851E-05"
        iyz="4.013458582149E-13"
        izz="0.000129727809308006" />
    </inertial>
    <visual>
      <origin
        xyz="0 0 0"
        rpy="0 0 0" />
      <geometry>
        <mesh
          filename="package://trossen_arm_description/meshes/leader/link_4.STL" />
      </geometry>
      <material
        name="">
        <color
          rgba="0.752941176470588 0.752941176470588 0.752941176470588 1" />
      </material>
    </visual>
    <collision>
      <origin
        xyz="0 0 0"
        rpy="0 0 0" />
      <geometry>
        <mesh
          filename="package://trossen_arm_description/meshes/leader/link_4.STL" />
      </geometry>
    </collision>
  </link>
  <joint
    name="joint_3"
    type="revolute">
    <origin
      xyz="0.181 0 0.06"
      rpy="0 0 0" />
    <parent
      link="link_3" />
    <child
      link="link_4" />
    <axis
      xyz="0 -1 0" />
    <limit
      lower="-2.42"
      upper="2.42"
      effort="0"
      velocity="0" />
  </joint>
  <link
    name="link_5">
    <inertial>
      <origin
        xyz="0.0688637418742179 -9.39598169223825E-09 -7.97490030540748E-05"
        rpy="0 0 0" />
      <mass
        value="0.206020694234339" />
      <inertia
        ixx="0.0001192555825672"
        ixy="1.28788670527638E-12"
        ixz="8.11487714374462E-09"
        iyy="0.000113486758261954"
        iyz="-2.20920499570922E-08"
        izz="7.43490729486467E-05" />
    </inertial>
    <visual>
      <origin
        xyz="0 0 0"
        rpy="0 0 0" />
      <geometry>
        <mesh
          filename="package://trossen_arm_description/meshes/leader/link_5.STL" />
      </geometry>
      <material
        name="">
        <color
          rgba="0.752941176470588 0.752941176470588 0.752941176470588 1" />
      </material>
    </visual>
    <collision>
      <origin
        xyz="0 0 0"
        rpy="0 0 0" />
      <geometry>
        <mesh
          filename="package://trossen_arm_description/meshes/leader/link_5.STL" />
      </geometry>
    </collision>
  </link>
  <joint
    name="joint_4"
    type="revolute">
    <origin
      xyz="0.08 0 0.0002"
      rpy="0 0 0" />
    <parent
      link="link_4" />
    <child
      link="link_5" />
    <axis
      xyz="0 0 -1" />
    <limit
      lower="-1.93"
      upper="1.93"
      effort="0"
      velocity="0" />
  </joint>
  <link
    name="gripper">
    <inertial>
      <origin
        xyz="0.0409143776757902 -0.00152071964896791 -0.0283260839735004"
        rpy="0 0 0" />
      <mass
        value="0.429245714150025" />
      <inertia
        ixx="0.000365804872293683"
        ixy="-7.45462945083529E-07"
        ixz="-3.38567206241593E-05"
        iyy="0.000251497793585492"
        iyz="-3.88856708726478E-06"
        izz="0.000174494714759548" />
    </inertial>
    <visual>
      <origin
        xyz="0 0 0"
        rpy="0 0 0" />
      <geometry>
        <mesh
          filename="package://trossen_arm_description/meshes/leader/gripper.STL" />
      </geometry>
      <material
        name="">
        <color
          rgba="0.752941176470588 0.752941176470588 0.752941176470588 1" />
      </material>
    </visual>
    <collision>
      <origin
        xyz="0 0 0"
        rpy="0 0 0" />
      <geometry>
        <mesh
          filename="package://trossen_arm_description/meshes/leader/gripper.STL" />
      </geometry>
    </collision>
  </link>
  <joint
    name="joint_5"
    type="revolute">
    <origin
      xyz="0.10353 0 0"
      rpy="0 0 0" />
    <parent
      link="link_5" />
    <child
      link="gripper" />
    <axis
      xyz="1 0 0" />
    <limit
      lower="-3.14159265359"
      upper="3.14159265359"
      effort="0"
      velocity="0" />
  </joint>
</robot>
